<?xml version="1.0" ?>
<!-- =================================================================================== -->
<!-- |    This document was autogenerated by xacro from mars_rover.urdf.xacro          | -->
<!-- |    EDITING THIS FILE BY HAND IS NOT RECOMMENDED                                 | -->
<!-- =================================================================================== -->
<!-- Name your robot here -->
<robot name="mars_rover">
  <link name="gazebo_base_link">
  </link>
  <joint name="gazebo_base_link" type="fixed">
    <parent link="gazebo_base_link"/>
    <child link="base_link"/>
  </joint>
  <link name="base_link">
    <inertial>
      <origin rpy="0 0 0" xyz="0.294653236941306 0.609822590999722 0.767801018571493"/>
      <mass value="64.9755690764331"/>
      <inertia ixx="1.53438421488244" ixy="-4.44679015831895E-16" ixz="2.21495001419508E-16" iyy="5.30184354246095" iyz="-5.65363072363094E-17" izz="6.56210187060195"/>
    </inertial>
    <visual>
      <origin rpy="0 0 0" xyz="0 0 0"/>
      <geometry>
        <mesh filename="package://mars_rover/meshes/base_link.STL"/>
      </geometry>
      <material name="">
        <color rgba="0.792156862745098 0.819607843137255 0.933333333333333 1"/>
      </material>
    </visual>
    <collision>
      <origin rpy="0 0 0" xyz="0 0 0"/>
      <geometry>
        <mesh filename="package://mars_rover/meshes/base_link.STL"/>
      </geometry>
    </collision>
  </link>
  <link name="front_wheel_left">
    <inertial>
      <origin rpy="0 0 0" xyz="0 0 -0.14132"/>
      <mass value="5.3936"/>
      <inertia ixx="0.081019" ixy="-1.7347E-18" ixz="-6.5857E-18" iyy="0.081019" iyz="3.003E-19" izz="0.017214"/>
    </inertial>
    <visual>
      <origin rpy="0 0 0" xyz="0 0 0"/>
      <geometry>
        <mesh filename="package://mars_rover/meshes/front_wheel_left.STL"/>
      </geometry>
      <material name="">
        <color rgba="0.79216 0.81961 0.93333 1"/>
      </material>
    </visual>
    <collision>
      <origin rpy="0 0 0" xyz="0 0 0"/>
      <geometry>
        <mesh filename="package://mars_rover/meshes/front_wheel_left.STL"/>
      </geometry>
    </collision>
  </link>
  <joint name="front_wheel_left_joint" type="continuous">
    <origin rpy="3.1416 0 1.4439" xyz="0.040653 -0.76402 0.22882"/>
    <parent link="base_link"/>
    <child link="front_wheel_left"/>
    <axis xyz="0 0 1"/>
    <limit effort="0" lower="0" upper="0" velocity="0"/>
  </joint>
  <link name="front_wheel_right">
    <inertial>
      <origin rpy="0 0 0" xyz="3.3307E-16 -8.3267E-17 0.23968"/>
      <mass value="5.3936"/>
      <inertia ixx="0.081019" ixy="-6.9389E-18" ixz="-7.6513E-17" iyy="0.081019" iyz="2.2799E-17" izz="0.017214"/>
    </inertial>
    <visual>
      <origin rpy="0 0 0" xyz="0 0 0"/>
      <geometry>
        <mesh filename="package://mars_rover/meshes/front_wheel_right.STL"/>
      </geometry>
      <material name="">
        <color rgba="0.79216 0.81961 0.93333 1"/>
      </material>
    </visual>
    <collision>
      <origin rpy="0 0 0" xyz="0 0 0"/>
      <geometry>
        <mesh filename="package://mars_rover/meshes/front_wheel_right.STL"/>
      </geometry>
    </collision>
  </link>
  <joint name="front_wheel_right_joint" type="continuous">
    <origin rpy="0 0 1.8307" xyz="0.040653 -0.76402 0.60982"/>
    <parent link="base_link"/>
    <child link="front_wheel_right"/>
    <axis xyz="0 0 1"/>
    <limit effort="0" lower="0" upper="0" velocity="0"/>
  </joint>
  <link name="rear_wheel_left">
    <inertial>
      <origin rpy="0 0 0" xyz="9.992E-15 1.8874E-15 -0.14132"/>
      <mass value="5.3936"/>
      <inertia ixx="0.081019" ixy="5.2042E-18" ixz="-3.6408E-16" iyy="0.081019" iyz="-3.6969E-16" izz="0.017214"/>
    </inertial>
    <visual>
      <origin rpy="0 0 0" xyz="0 0 0"/>
      <geometry>
        <mesh filename="package://mars_rover/meshes/rear_wheel_left.STL"/>
      </geometry>
      <material name="">
        <color rgba="0.79216 0.81961 0.93333 1"/>
      </material>
    </visual>
    <collision>
      <origin rpy="0 0 0" xyz="0 0 0"/>
      <geometry>
        <mesh filename="package://mars_rover/meshes/rear_wheel_left.STL"/>
      </geometry>
    </collision>
  </link>
  <joint name="rear_wheel_left_joint" type="continuous">
    <origin rpy="-3.1416 0 -0.30763" xyz="0.54865 -0.76402 0.22882"/>
    <parent link="base_link"/>
    <child link="rear_wheel_left"/>
    <axis xyz="0 0 1"/>
    <limit effort="0" lower="0" upper="0" velocity="0"/>
  </joint>
  <link name="rear_wheel_right">
    <inertial>
      <origin rpy="0 0 0" xyz="-2.1427E-14 -2.1316E-14 0.23968"/>
      <mass value="5.3936"/>
      <inertia ixx="0.081019" ixy="0" ixz="5.6667E-15" iyy="0.081019" iyz="5.6654E-15" izz="0.017214"/>
    </inertial>
    <visual>
      <origin rpy="0 0 0" xyz="0 0 0"/>
      <geometry>
        <mesh filename="package://mars_rover/meshes/rear_wheel_right.STL"/>
      </geometry>
      <material name="">
        <color rgba="0.79216 0.81961 0.93333 1"/>
      </material>
    </visual>
    <collision>
      <origin rpy="0 0 0" xyz="0 0 0"/>
      <geometry>
        <mesh filename="package://mars_rover/meshes/rear_wheel_right.STL"/>
      </geometry>
    </collision>
  </link>
  <joint name="rear_wheel_right_joint" type="continuous">
    <origin rpy="0 0 -1.8864" xyz="0.54865 -0.76402 0.60982"/>
    <parent link="base_link"/>
    <child link="rear_wheel_right"/>
    <axis xyz="0 0 1"/>
    <limit effort="0" lower="0" upper="0" velocity="0"/>
  </joint>
  <transmission name="trans_front_wheel_left">
    <type>transmission_interface/SimpleTransmission</type>
    <joint name="front_wheel_left_joint">
      <hardwareInterface>VelocityJointInterface</hardwareInterface>
    </joint>
    <actuator name="front_wheel_left_motor">
      <hardwareInterface>VelocityJointInterface</hardwareInterface>
    </actuator>
  </transmission>
  <transmission name="trans_front_wheel_right">
    <type>transmission_interface/SimpleTransmission</type>
    <joint name="front_wheel_right_joint">
      <hardwareInterface>VelocityJointInterface</hardwareInterface>
    </joint>
    <actuator name="front_wheel_right_motor">
      <hardwareInterface>VelocityJointInterface</hardwareInterface>
    </actuator>
  </transmission>
  <transmission name="trans_rear_wheel_left">
    <type>transmission_interface/SimpleTransmission</type>
    <joint name="rear_wheel_left_joint">
      <hardwareInterface>VelocityJointInterface</hardwareInterface>
    </joint>
    <actuator name="rear_wheel_rleft_motor">
      <hardwareInterface>VelocityJointInterface</hardwareInterface>
    </actuator>
  </transmission>
  <transmission name="trans_rear_wheel_right">
    <type>transmission_interface/SimpleTransmission</type>
    <joint name="rear_wheel_right_joint">
      <hardwareInterface>VelocityJointInterface</hardwareInterface>
    </joint>
    <actuator name="rear_wheel_right_motor">
      <hardwareInterface>VelocityJointInterface</hardwareInterface>
    </actuator>
  </transmission>
  <link name="base_laser">
    <inertial>
      <origin rpy="0 0 0" xyz="-0.00029774 0.0066667 0.00013047"/>
      <mass value="0.15717"/>
      <inertia ixx="6.7885E-05" ixy="-1.3987E-07" ixz="-8.1554E-07" iyy="0.00013173" iyz="-9.0932E-08" izz="7.1972E-05"/>
    </inertial>
    <visual>
      <origin rpy="0 0 0" xyz="0 0 0"/>
      <geometry>
        <mesh filename="package://ydlidar_ros/meshes/ydlidar.dae"/>
      </geometry>
      <material name="">
        <color rgba="0.64706 0.61961 0.58824 1"/>
      </material>
    </visual>
    <collision>
      <origin rpy="0 0 0" xyz="0 0 0"/>
      <geometry>
        <mesh filename="package://ydlidar_ros/meshes/ydlidar.dae"/>
      </geometry>
    </collision>
  </link>
  <link name="laser_frame">
    <inertial>
      <origin rpy="0 0 0" xyz="-0.00036659 0.00064155 -0.00027052"/>
      <mass value="0.25482"/>
      <inertia ixx="8.9194E-05" ixy="1.8116E-07" ixz="3.6435E-08" iyy="0.00018279" iyz="2.423E-07" izz="0.00011103"/>
    </inertial>
    <!--visual>
      <origin
        xyz="0 0 0"
        rpy="0 0 0" />
      <geometry>
        <mesh
          filename="package://ydlidar_ros/meshes/ydlidar.dae" />
      </geometry>
      <material
        name="">
        <color
          rgba="0.64706 0.61961 0.58824 1" />
      </material>
    </visual-->
    <!--collision>
      <origin
        xyz="0 0 0"
        rpy="0 0 0" />
      <geometry>
        <mesh
          filename="package://ydlidar_ros/meshes/ydlidar.dae" />
      </geometry>
    </collision-->
  </link>
  <joint name="laser_joint" type="fixed">
    <origin rpy="0 0 0" xyz="0 0 0.03172"/>
    <parent link="base_laser"/>
    <child link="laser_frame"/>
    <axis xyz="0 0 0"/>
  </joint>
  <!-- Add your gazebo sensors here -->
  <gazebo reference="base_laser">
    <!-- <gravity>true</gravity> -->
    <!-- Gazebo has fixed set of Sensors types. Check them out here <> -->
    <sensor name="laser" type="ray">
      <!-- Add in your sensor characteristics -->
      <pose> 0 0 0 0 0 0 </pose>
      <visualise>true</visualise>
      <update_rate>40</update_rate>
      <!-- <always_on>true</always_on> -->
      <ray>
        <scan>
          <horizontal>
            <samples>720</samples>
            <resolution>1</resolution>
            <min_angle>-1.570796</min_angle>
            <max_angle>1.570796</max_angle>
          </horizontal>
        </scan>
        <range>
          <min>0.10</min>
          <max>30.0</max>
          <resolution>0.01</resolution>
        </range>
        <noise>
          <type>gaussian</type>
          <mean>0.0</mean>
          <stddev>0.01</stddev>
        </noise>
      </ray>
      <plugin filename="libgazebo_ros_laser.so" name="gazebo_ros_head_hokuyo_controller">
        <!-- Use topic name as /my_robot/scan -->
        <topicName/>
        <frameName>laser_frame</frameName>
      </plugin>
    </sensor>
  </gazebo>
  <!--  Gazebo plugin for control here is already added for you -->
  <gazebo>
    <plugin filename="libgazebo_ros_control.so" name="gazebo_ros_control">
      <robotNamespace>/simple_car</robotNamespace>
      <robotSimType>gazebo_ros_control/DefaultRobotHWSim</robotSimType>
      <legacyModeNS>true</legacyModeNS>
    </plugin>
  </gazebo>
  <!-- Create a joint between your robot and sensor -->
  <joint name="base_laser_joint" type="fixed">
    <parent link="base_link"/>
    <child link="base_laser"/>
    <axis xyz="0 0 0"/>
  </joint>
</robot>
