<?xml version="1.0" encoding="utf-8"?>
<!-- This URDF was automatically created by SolidWorks to URDF Exporter! Originally created by Stephen Brawner (brawner@gmail.com) 
     Commit Version: 1.6.0-1-g15f4949  Build Version: 1.6.7594.29634
     For more information, please see http://wiki.ros.org/sw_urdf_exporter -->
<robot
  name="mars_rover">
  <link
    name="base_link">
    <inertial>
      <origin
        xyz="0.294653236941306 0.609822590999722 0.767801018571493"
        rpy="0 0 0" />
      <mass
        value="64.9755690764331" />
      <inertia
        ixx="1.53438421488244"
        ixy="-4.44679015831895E-16"
        ixz="2.21495001419508E-16"
        iyy="5.30184354246095"
        iyz="-5.65363072363094E-17"
        izz="6.56210187060195" />
    </inertial>
    <visual>
      <origin
        xyz="0 0 0"
        rpy="0 0 0" />
      <geometry>
        <mesh
          filename="package://mars_rover/meshes/base_link.STL" />
      </geometry>
      <material
        name="">
        <color
          rgba="0.792156862745098 0.819607843137255 0.933333333333333 1" />
      </material>
    </visual>
    <collision>
      <origin
        xyz="0 0 0"
        rpy="0 0 0" />
      <geometry>
        <mesh
          filename="package://mars_rover/meshes/base_link.STL" />
      </geometry>
    </collision>
  </link>
  <link
    name="front_wheel_left">
    <inertial>
      <origin
        xyz="0 0 -0.14132"
        rpy="0 0 0" />
      <mass
        value="5.3936" />
      <inertia
        ixx="0.081019"
        ixy="-1.7347E-18"
        ixz="-6.5857E-18"
        iyy="0.081019"
        iyz="3.003E-19"
        izz="0.017214" />
    </inertial>
    <visual>
      <origin
        xyz="0 0 0"
        rpy="0 0 0" />
      <geometry>
        <mesh
          filename="package://mars_rover/meshes/front_wheel_left.STL" />
      </geometry>
      <material
        name="">
        <color
          rgba="0.79216 0.81961 0.93333 1" />
      </material>
    </visual>
    <collision>
      <origin
        xyz="0 0 0"
        rpy="0 0 0" />
      <geometry>
        <mesh
          filename="package://mars_rover/meshes/front_wheel_left.STL" />
      </geometry>
    </collision>
  </link>
  <joint
    name="front_wheel_left_joint"
    type="continuous">
    <origin
      xyz="0.040653 -0.76402 0.22882"
      rpy="3.1416 0 1.4439" />
    <parent
      link="base_link" />
    <child
      link="front_wheel_left" />
    <axis
      xyz="0 0 1" />
    <limit
      lower="0"
      upper="0"
      effort="0"
      velocity="0" />
  </joint>
  <link
    name="front_wheel_right">
    <inertial>
      <origin
        xyz="3.3307E-16 -8.3267E-17 0.23968"
        rpy="0 0 0" />
      <mass
        value="5.3936" />
      <inertia
        ixx="0.081019"
        ixy="-6.9389E-18"
        ixz="-7.6513E-17"
        iyy="0.081019"
        iyz="2.2799E-17"
        izz="0.017214" />
    </inertial>
    <visual>
      <origin
        xyz="0 0 0"
        rpy="0 0 0" />
      <geometry>
        <mesh
          filename="package://mars_rover/meshes/front_wheel_right.STL" />
      </geometry>
      <material
        name="">
        <color
          rgba="0.79216 0.81961 0.93333 1" />
      </material>
    </visual>
    <collision>
      <origin
        xyz="0 0 0"
        rpy="0 0 0" />
      <geometry>
        <mesh
          filename="package://mars_rover/meshes/front_wheel_right.STL" />
      </geometry>
    </collision>
  </link>
  <joint
    name="front_wheel_right_joint"
    type="continuous">
    <origin
      xyz="0.040653 -0.76402 0.60982"
      rpy="0 0 1.8307" />
    <parent
      link="base_link" />
    <child
      link="front_wheel_right" />
    <axis
      xyz="0 0 1" />
    <limit
      lower="0"
      upper="0"
      effort="0"
      velocity="0" />
  </joint>
  <link
    name="rear_wheel_left">
    <inertial>
      <origin
        xyz="9.992E-15 1.8874E-15 -0.14132"
        rpy="0 0 0" />
      <mass
        value="5.3936" />
      <inertia
        ixx="0.081019"
        ixy="5.2042E-18"
        ixz="-3.6408E-16"
        iyy="0.081019"
        iyz="-3.6969E-16"
        izz="0.017214" />
    </inertial>
    <visual>
      <origin
        xyz="0 0 0"
        rpy="0 0 0" />
      <geometry>
        <mesh
          filename="package://mars_rover/meshes/rear_wheel_left.STL" />
      </geometry>
      <material
        name="">
        <color
          rgba="0.79216 0.81961 0.93333 1" />
      </material>
    </visual>
    <collision>
      <origin
        xyz="0 0 0"
        rpy="0 0 0" />
      <geometry>
        <mesh
          filename="package://mars_rover/meshes/rear_wheel_left.STL" />
      </geometry>
    </collision>
  </link>
  <joint
    name="rear_wheel_left_joint"
    type="continuous">
    <origin
      xyz="0.54865 -0.76402 0.22882"
      rpy="-3.1416 0 -0.30763" />
    <parent
      link="base_link" />
    <child
      link="rear_wheel_left" />
    <axis
      xyz="0 0 1" />
    <limit
      lower="0"
      upper="0"
      effort="0"
      velocity="0" />
  </joint>
  <link
    name="rear_wheel_right">
    <inertial>
      <origin
        xyz="-2.1427E-14 -2.1316E-14 0.23968"
        rpy="0 0 0" />
      <mass
        value="5.3936" />
      <inertia
        ixx="0.081019"
        ixy="0"
        ixz="5.6667E-15"
        iyy="0.081019"
        iyz="5.6654E-15"
        izz="0.017214" />
    </inertial>
    <visual>
      <origin
        xyz="0 0 0"
        rpy="0 0 0" />
      <geometry>
        <mesh
          filename="package://mars_rover/meshes/rear_wheel_right.STL" />
      </geometry>
      <material
        name="">
        <color
          rgba="0.79216 0.81961 0.93333 1" />
      </material>
    </visual>
    <collision>
      <origin
        xyz="0 0 0"
        rpy="0 0 0" />
      <geometry>
        <mesh
          filename="package://mars_rover/meshes/rear_wheel_right.STL" />
      </geometry>
    </collision>
  </link>
  <joint
    name="rear_wheel_right_joint"
    type="continuous">
    <origin
      xyz="0.54865 -0.76402 0.60982"
      rpy="0 0 -1.8864" />
    <parent
      link="base_link" />
    <child
      link="rear_wheel_right" />
    <axis
      xyz="0 0 1" />
    <limit
      lower="0"
      upper="0"
      effort="0"
      velocity="0" />
  </joint>
 
  <transmission name="trans_front_wheel_left">
  <type>transmission_interface/SimpleTransmission</type>
  <joint name="front_wheel_left_joint">
  <hardwareInterface>VelocityJointInterface</hardwareInterface>
  </joint>
  <actuator name="front_wheel_left_motor">
  <hardwareInterface>VelocityJointInterface</hardwareInterface>
  </actuator>
  </transmission>

  <transmission name="trans_front_wheel_right">
  <type>transmission_interface/SimpleTransmission</type>
  <joint name="front_wheel_right_joint">
  <hardwareInterface>VelocityJointInterface</hardwareInterface>
  </joint>
  <actuator name="front_wheel_right_motor">
  <hardwareInterface>VelocityJointInterface</hardwareInterface>
  </actuator>
  </transmission>

  <transmission name="trans_rear_wheel_left">
  <type>transmission_interface/SimpleTransmission</type>
  <joint name="rear_wheel_left_joint">
  <hardwareInterface>VelocityJointInterface</hardwareInterface>
  </joint>
  <actuator name="rear_wheel_rleft_motor">
  <hardwareInterface>VelocityJointInterface</hardwareInterface>
  </actuator>
  </transmission>

  <transmission name="trans_rear_wheel_right">
  <type>transmission_interface/SimpleTransmission</type>
  <joint name="rear_wheel_right_joint">
  <hardwareInterface>VelocityJointInterface</hardwareInterface>
  </joint>
  <actuator name="rear_wheel_right_motor">
  <hardwareInterface>VelocityJointInterface</hardwareInterface>
  </actuator>
  </transmission>
</robot>